Workbook

Sheet Companies_Results
A1: Company Details | B1: Company Details | T1: Company Details | U1: Company Details | V1: Company Details | W1: Size Metrics | X1: Financials | Y1: Company Details | Z1: Company Details | AA1: Financials | AB1: Company Details | AC1: Industry | AD1: Industry | AE1: Industry | AF1: Industry
A2: Company Details | B2: Company Details | T2: Company Details | U2: Company Location | V2: Company Details | W2: Size Metrics | X2: Income Statement | Y2: Company Location | Z2: Company Location | AA2: Balance Sheet | AB2: Company Details | AC2: Industry Company Details | AD2: Industry Company Details | AE2: Industry Company Details | AF2: Industry Company Details
AC3: Primary RBICS | AD3: Primary RBICS | AE3: Primary RBICS | AF3: Primary RBICS
A4: Identifier | B4: Name | C4: Propose to Include? | D4: Outreach | E4: Identified Contact | F4: Status | G4: Connect4 Data | H4: IBISworld Data | I4: MarketLine Data | J4: ANZREU Purchases? | K4: Reported Emissions | L4: Project Classification | M4: Year | N4: Reported - Scope 1 | O4: Reported - Scope 2 | P4: CER 2023-24 Scope 1 | Q4: CER 2023-24 Scope 2 | R4: EBITDA (MM) (AUD) | S4: Net Income (MM) (AUD) | T4: Company Type Main | U4: Company Country | V4: Year Founded | W4: Number of Employees | X4: Revenue (MM) (AUD) | Y4: Company Region | Z4: Company State | AA4: Total Assets (MM) (AUD) | AB4: Business Description | AC4: Primary FactSet RBICS Industry Group | AD4: Primary FactSet RBICS Sub Sector | AE4: Primary FactSet RBICS Sector | AF4: Primary FactSet RBICS Industry | AH4: Extracted Scope 1 (kgCO2e) | AI4: Scope 1 Confidence | AJ4: Scope 1 Context | AK4: Extracted Scope 2 (kgCO2e) | AL4: Scope 2 Confidence | AM4: Scope 2 Context | AN4: Extracted Scope 3 (kgCO2e) | AO4: Scope 3 Confidence | AP4: Scope 3 Context | AQ4: Net Zero Mentions | AR4: Profitability Ratio | AS4: Reputational Concern Ratio
B5: Nestle | D5: AC | F5: Agreed to interview. | R5: =IFERROR(_xlfn.XLOOKUP($A5,Profitability!$A$5:$A$342,Profitability!$Q$5:$Q$342),"na") | S5: =IFERROR(_xlfn.XLOOKUP($A5,Profitability!$A$5:$A$342,Profitability!$R$5:$R$342),"na")
A6: WDS-AU | B6: Woodside Energy Group Ltd. | D6: KH | E6: Harold Yap | F6: Agreed to questionnaire. | P6: 8421985 | Q6: 5330 | R6: =IFERROR(_xlfn.XLOOKUP($A6,Profitability!$A$5:$A$342,Profitability!$Q$5:$Q$342),"na") | S6: =IFERROR(_xlfn.XLOOKUP($A6,Profitability!$A$5:$A$342,Profitability!$R$5:$R$342),"na") | T6: Public | U6: Australia | V6: 1971 | W6: 4718 | X6: 21202.274 | Y6: Pacific | Z6: Western Australia (WA) | AA6: 98948.555 | AB6: Woodside Energy Group Ltd. engages in the exploration, evaluation, development, and production of hydrocarbon and oil and gas properties. It operates through the following segments: North West Shelf, Pluto, Australia Oil, Wheatstone, Development, and Others. The North West Shelf segment produces liquefied natural gas, pipeline natural gas, condensate, liquefied petroleum gas and crude oil from the North West Shelf ventures. The Pluto segment develops liquefied natural gas in assigned permit areas. The Australia Oil segment is involved in the exploration, evaluation, development, production and sale of crude oil in assigned permit areas. The Wheatstone segment is involved in the exploration, evaluation, and development of liquefied natural gas, pipeline natural gas, and condensate. The Development segment includes the exploration of gas resources in Scarborough, Sangomar, and other project areas. The Other segment is composed of the activities undertaken by exploration, international and Sunrise Business Units. The company was founded on July 26, 1954 and is headquartered in Perth, Australia. | AC6: Other Fossil Fuel Exploration and Production | AD6: Fossil Fuel Exploration and Production | AE6: Upstream Energy | AF6: Asia/Pacific Fossil Fuel Exploration/Production | AH6: 5437000 | AI6: 0.9 | AJ6: === Table 4 (page 5) === HIGHLIGHTS,CONFIDENCE IN LNG,SCOPE 1 AND 2,NEW ENERGY | AK6: 6320000 | AL6: 0.9 | AM6: ,"compared to historical and/or current conventions or analogues, for example relating to an otherwise similar resource, process,",, ,,Starting base,Woodside uses a starting base of 6.32 Mt CO2-e which is representative of the gross annual average equity Scope 1 and 2 ,"production facility, product or service, or activity. When applied to Woodside's strategy, please see the definition of lower-carbon",,greenhouse gas emissions over 2016-2020 and which may be adjusted (up or down) for potential equity changes in producing | AN6: 3000 | AO6: 0.9 | AP6: ,methane emissions benchmarks., • This is reinforced by firm demand side commitments to,,Scope 3 targets.18 "offtake, with over 15 Mt of LNG contracted to Asian buyers",• We are pursuing emissions reduction opportunities and, | AQ6: 8 | AR6: 0.255488 | AS6: 0.000377
A7: BHP-AU | B7: BHP Group Ltd. | D7: KH | E7: Tom McKeon | F7: Invitation sent | M7: 2025 | N7: =7.4*10^6 | O7: =1.3*10^6 | P7: 3698759 | Q7: 1314290 | R7: =IFERROR(_xlfn.XLOOKUP($A7,Profitability!$A$5:$A$342,Profitability!$Q$5:$Q$342),"na") | S7: =IFERROR(_xlfn.XLOOKUP($A7,Profitability!$A$5:$A$342,Profitability!$R$5:$R$342),"na") | T7: Public | U7: Australia | V7: 1885 | W7: - | X7: 79153.099 | Y7: Pacific | Z7: Victoria (VIC) | AA7: 166002.9 | AB7: BHP Group Ltd. engages in the exploration, development, production and processing of iron ore, metallurgical coal, and copper. It operates through the following segments: Copper, Iron Ore, and Coal. The Copper segment refers to the mining of copper, silver, lead, zinc, molybdenum, uranium, and gold. The Iron Ore segment involves in the mining of iron ore. The Coal segment focuses on metallurgical coal and energy coal. The company was founded on August 13, 1885 and is headquartered in Melbourne, Australia. | AC7: Base Metal Mining | AD7: Metal Ore Mining | AE7: Mining and Mineral Products | AF7: Other Base Metal Ore Mining | AH7: 7400000 | AI7: 1 | AJ7: ,,FY2025,FY2024,FY2023 Total,Scope 1 emissions,7.4,8.1,8.0 operations,,,, | AK7: 1300000 | AL7: 1 | AM7: line with its strategy and risk management process,,,, "b) Disclose Scope 1, Scope 2, and, if appropriate,",Pages 48 to 53,–,–,– "Scope 3 GHG emissions, and the related risks",,,, | AN7: 378200000 | AO7: 1 | AP7: 3.7" Total Scope 3 emissions,"378.2 377.7 | AQ7: 98 | AR7: 0.175939 | AS7: 0.001238
A8: MIN-AU | B8: Mineral Resources Ltd. | D8: KH | E8: Laurren Duncan | F8: Invitation sent | P8: 704979 | Q8: 11055 | R8: =IFERROR(_xlfn.XLOOKUP($A8,Profitability!$A$5:$A$342,Profitability!$Q$5:$Q$342),"na") | S8: =IFERROR(_xlfn.XLOOKUP($A8,Profitability!$A$5:$A$342,Profitability!$R$5:$R$342),"na") | T8: Public | U8: Australia | V8: 2006 | W8: 8456 | X8: 4472 | Y8: Pacific | Z8: Western Australia (WA) | AA8: 11927 | AB8: Mineral Resources Ltd. engages in mining and processing of mineral properties. The firm operates through the following segments: Mining Services, Iron Ore, Energy, Lithium, Other Commodities, and Central. It offers contract crushing, infrastructure, and recovery of base metals concentrate. The company was founded by Christopher J. Ellison on February 27, 2006, and is headquartered in Perth, Australia. | AC8: Base Metal Mining | AD8: Metal Ore Mining | AE8: Mining and Mineral Products | AF8: Other Base Metal Ore Mining | AH8: 731084 | AI8: 1 | AJ8: Total Scope 1 GHG emissions (tCO2-e),"731,084" | AK8: 150947 | AL8: 1 | AM8: High Impact Environmental Incidents (Level 4 and, ,0 above), | AQ8: 23 | AR8: -0.202147 | AS8: 0.005143
A9: LTR-AU | B9: Liontown Resources Ltd. | D9: KH | E9: Secondary only. Requested. | F9: Invitation sent | R9: =IFERROR(_xlfn.XLOOKUP($A9,Profitability!$A$5:$A$342,Profitability!$Q$5:$Q$342),"na") | S9: =IFERROR(_xlfn.XLOOKUP($A9,Profitability!$A$5:$A$342,Profitability!$R$5:$R$342),"na") | T9: Public | U9: Australia | V9: 2006 | W9: - | X9: 0 | Y9: Pacific | Z9: Western Australia (WA) | AA9: 1384.924 | AB9: Liontown Resources Ltd. engages in the exploration and evaluation of minerals. Its projects include Kathleen Valley, Buldania, Moora Gold-PGE-Ni-Cu, and Toolebuc. The company was founded on February 2, 2006 and is headquartered in West Perth, Australia. | AC9: Base Metal Mining | AD9: Metal Ore Mining | AE9: Mining and Mineral Products | AF9: Lithium Ore Mining | AH9: 35822 | AI9: 0.9 | AJ9: Scope 1,tCO2-e,"35,822.02","41,605.88" | AK9: 9276 | AL9: 0.9 | AM9: Scope 2,tCO2-e,"9,217.31","1,891.67" | AN9: 0 | AQ9: 0
A10: WHC-AU | B10: Whitehaven Coal Ltd. | D10: KH | E10: Secondary only. Requested. | F10: Invitation sent | P10: 1228004 | Q10: 137673 | R10: =IFERROR(_xlfn.XLOOKUP($A10,Profitability!$A$5:$A$342,Profitability!$Q$5:$Q$342),"na") | S10: =IFERROR(_xlfn.XLOOKUP($A10,Profitability!$A$5:$A$342,Profitability!$R$5:$R$342),"na") | T10: Public | U10: Australia | V10: 2007 | W10: - | X10: 5832 | Y10: Pacific | Z10: New South Wales (NSW) | AA10: 12227 | AB10: Whitehaven Coal Ltd. engages in the development and operation of coal mines. The firm operates through the following segments: Open Cut Operations and Underground Operations. Its projects include Canyon, Maules Creek, Narrabri North, Rocglen, Sunnyside, Tarrawonga, Vickery, Werris Creek and Other Projects. The company was founded by Keith Ross in 1999 and is headquartered in Sydney, Australia. | AC10: Asia/Pacific International Coal Mining | AD10: Coal and Uranium Mining | AE10: Upstream Energy | AF10: Asia/Pacific International Coal Mining | AH10: 1958000 | AI10: 1 | AJ10: === Table 8 (page 32) === and Daunia mines. Scope 1 emissions,offsetting Scope 2 emissions on a whole-,,,,,, ,,,,,"1,958",, | AK10: 271000 | AL10: 1 | AM10: ,,,for June Qtr,,51% ,Our Scope 2 emissions (location based),,271,, ,"totalled 271 kt CO2-e, with the increase",,,, | AQ10: 8 | AR10: 0.111283 | AS10: 0.001372
A11: WES-AU | B11: Wesfarmers Ltd. | D11: KH | E11: Kylie Ashenbrenner | F11: Invitation sent | P11: 826977 | Q11: 485184 | R11: =IFERROR(_xlfn.XLOOKUP($A11,Profitability!$A$5:$A$342,Profitability!$Q$5:$Q$342),"na") | S11: =IFERROR(_xlfn.XLOOKUP($A11,Profitability!$A$5:$A$342,Profitability!$R$5:$R$342),"na") | T11: Public | U11: Australia | V11: 1981 | W11: 118000 | X11: 45576 | Y11: Pacific | Z11: Western Australia (WA) | AA11: 30269.001 | AB11: Wesfarmers Ltd. engages in the provision of fresh food, groceries, general merchandise, liquor, fuel, and financial services. It operates through the following segments: Bunnings; Kmart Group; Chemicals, Energy, and Fertilisers (WesCEF); Officeworks; Industrial and Safety; Health; Catch; and Other. The Bunnings segment consists of retailers of building materials and home and garden improvement products and servicing households and commercial customers including builders, trades, and businesses. The Kmart Group segment comprises of Kmart and Target which are retailers of apparel and general merchandise, including toys, leisure, entertainment, home, and consumable; and Catch which is an online retailer offering branded products on a first-party basis and a third-party online marketplace. The WesCEF segment refers to manufacturer and marketer of chemicals for industry, mining, mineral processing, broadacre and horticultural fertilisers, marketer and distributor of LPG and LNG; and manufacturer of wood-plastic composite decking and screening products. The Officeworks segment covers the retail and supply of office products and solutions for households, small-to-medium sized businesses, and the education sector. The Industrial and Safety segment supplies and distributes maintenance, repair, and operating products; manufactures and markets industrial gases and equipment; supplies, manufactures, and distributes workwear clothing in Australia and internationally. The Health segment wholesales and retails pharmaceutical, health, wellbeing, and beauty products. The Catch segment operates as an online retailer offering branded products on first-party basis and a third-party online marketplace. The Other segment includes food and stables retailing; forest products; property; investment banking; OneDigital, and Corporate. The company was founded in 1914 and is headquartered in Perth, Australia. | AC11: Mixed Home Improvement and Furnishings Stores | AD11: Home Improvement Retail | AE11: Consumer Retail | AF11: Mixed Home Improvement and Furnishings Stores | AH11: 789700 | AI11: 1 | AJ11: ,and others in the sectors in which, focus on reducing operational Scope 1,,financial disclosure requirements apply ,they operate., | AK11: 236900 | AL11: 1 | AM11: ,they operate., and Scope 2 greenhouse gas emissions,,to the Group from 1 July 2025 for financial (operational emissions). All divisions have,"This year, we established cross-functional",year 2026 reporting. As the ASRS S2 | AN11: 30500000 | AO11: 1 | AP11: and value chains.,, The Group’s Scope 31 emissions arise from,The Group’s Scope 3 emissions are,Category 4 — Upstream transportation "a wide range of activities across suppliers,",concentrated in four categories and those,and distribution includes emissions that | AQ11: 24 | AR11: 0.0642 | AS11: 0.000527
A12: QAN-AU | B12: Qantas Airways Ltd. | D12: KH | E12: Darren Wee | F12: Invitation sent | P12: 4528002 | Q12: 59740 | R12: =IFERROR(_xlfn.XLOOKUP($A12,Profitability!$A$5:$A$342,Profitability!$Q$5:$Q$342),"na") | S12: =IFERROR(_xlfn.XLOOKUP($A12,Profitability!$A$5:$A$342,Profitability!$R$5:$R$342),"na") | T12: Public | U12: Australia | V12: 1950 | W12: 25000 | X12: 23409 | Y12: Pacific | Z12: New South Wales (NSW) | AA12: 23356.001 | AB12: Qantas Airways Ltd. engages in international and domestic air transportation services. It operates through the following segments: Qantas Domestic, Qantas International, Jetstar Group, Qantas Loyalty, and Corporate. The Qantas Domestic segment is involved in the carrier in the Australian domestic market measured by capacity. The Qantas International segment refers to the carrier into and out of Australia, also targeting business and leisure customers who value the full-service experience. The Jetstar Group segment focuses on operations in Australia, delivering low fares and a differentiated product offering to the price-sensitive market. The Qantas Loyalty segment consists of consumer and SME coalition loyalty programs. The Corporate segment refers to centralized management and governance of the Qantas Group. The company was founded on November 16, 1920 and is headquartered in Mascot, Australia. | AC12: Air Passenger Transportation | AD12: Passenger Transportation | AE12: Industrial Services | AF12: Asia/Pacific Air Passenger Service Providers | AH12: 12139425 | AJ12: FY25 Scope 1 emissions (tCO₂e). | AK12: 58106 | AM12: FY25 Global Scope 2 GHG emissions (tCO₂e) (location-based method). | AN12: 7305845 | AP12: FY25 Scope 3 emissions (tCO₂e). | AQ12: 30 | AR12: 0.068563 | AS12: 0.001282
A13: MGR-AU | B13: Mirvac Group | D13: KH | E13: Secondary only. Requested. | F13: Invitation sent | R13: =IFERROR(_xlfn.XLOOKUP($A13,Profitability!$A$5:$A$342,Profitability!$Q$5:$Q$342),"na") | S13: =IFERROR(_xlfn.XLOOKUP($A13,Profitability!$A$5:$A$342,Profitability!$R$5:$R$342),"na") | T13: Public | U13: Australia | V13: 1972 | W13: 1651 | X13: 2466 | Y13: Pacific | Z13: New South Wales (NSW) | AA13: 15290 | AB13: Mirvac Group engages in real estate investment, development, third party capital management, and property asset management. It operates through the following segments: Investment, Funds, and Development. The Investment segment focuses on directly owned assets, co-investment stakes in funds, and investments in joint ventures and associates alongside capital partners. The Funds segment includes both funds management and asset management operations. The Development segment deals with commercial and mixed-use, build to rent, and residential projects. The company was founded by Henry Pollack and Robert Hamilton in 1972 and is headquartered in Sydney, Australia. | AC13: Equity REITs | AD13: Real Estate Investment Trusts (REITs) | AE13: Real Estate | AF13: Equity REITs | AH13: 6618 | AI13: 1 | AJ13: Total Scope 1,"6,618","9,632","10,711","9,371", | AK13: 73110 | AL13: 1 | AM13: Total Scope 2,"73,110",—,—,—, | AN13: 0 | AQ13: 0 | AR13: 0.027575 | AS13: 0
A14: ILU-AU | B14: Iluka Resources Ltd. | D14: KH | E14: Sarah Hodgson | F14: Invitation sent | R14: =IFERROR(_xlfn.XLOOKUP($A14,Profitability!$A$5:$A$342,Profitability!$Q$5:$Q$342),"na") | S14: =IFERROR(_xlfn.XLOOKUP($A14,Profitability!$A$5:$A$342,Profitability!$R$5:$R$342),"na") | T14: Public | U14: Australia | V14: 1954 | W14: 971 | X14: 1170.3 | Y14: Pacific | Z14: Western Australia (WA) | AA14: 3925.1999 | AB14: Iluka Resources Ltd. engages in the exploration, development, mining, processing, marketing, and rehabilitation of mineral sands products. It operates through the following segments: Jacinth-Ambrosia/Mid West (JA/MW), Cataby/South West (C/SW), Rare Earths (RE), and United States/Murray Basin (US/MB). The JA/MW segment deals with mining operations at Jacinth-Ambrosia located in South Australia, and associated processing operations at the Narngulu mineral separation plant in mid-west Western Australia. The C/SW segment represents mining activities at Cataby and processing of ilmenite at Synthetic Rutile Kilns 1 and 2, located in Western Australia. The RE segment refers to the Eneabba Rare Earths Refinery, which is currently being constructed in Western Australia and associated feasibility studies alongside Phase 1 and 2 of the Eneabba development, and the Group's investment in Northern Minerals Limited. The US/MB segment focuses on rehabilitation obligations in Florida and Virginia, and certain idle assets located in Australia. The company was founded on July 24, 1954 and is headquartered in Perth, Australia. | AC14: Base Metal Mining | AD14: Metal Ore Mining | AE14: Mining and Mineral Products | AF14: Non-Ferrous Metal Ore Mining | AH14: 392000 | AJ14: 2024 Scope 1 emissions (392 ktCO2e). | AK14: 71000 | AM14: 2024 Scope 2 emissions (71 ktCO2e). | AN14: 0 | AP14: Iluka is currently examining its scope 3 emissions and intends to disclose this information in future reports. | AQ14: 1 | AR14: 0.197642 | AS14: 0.000854
A15: RHC-AU | B15: Ramsay Health Care Ltd. | D15: KH | E15: Siobhan Leach | F15: Invitation sent | P15: 16136 | Q15: 131592 | R15: =IFERROR(_xlfn.XLOOKUP($A15,Profitability!$A$5:$A$342,Profitability!$Q$5:$Q$342),"na") | S15: =IFERROR(_xlfn.XLOOKUP($A15,Profitability!$A$5:$A$342,Profitability!$R$5:$R$342),"na") | T15: Public | U15: Australia | V15: 1975 | W15: 90000 | X15: 17791.6 | Y15: Pacific | Z15: New South Wales (NSW) | AA15: 22959.801 | AB15: Ramsay Health Care Ltd. engages in the healthcare services and the operation of hospitals and day surgery facilities. It operates through the following geographical segments : Asia Pacific, UK, France and Nordics. The company was founded by Paul Joseph Ramsay in 1964 and is headquartered in Sydney, Australia. | AC15: Acute Care and Institutional Patient Care | AD15: Patient Care | AE15: Healthcare Services | AF15: General and Acute Hospitals | AH15: 88711 | AJ15: FY25 Group Scope 1 emissions (tCO2-e) derived from summing Gas and fuel (59,949), Anaesthetic gases (26,244), and Refrigerants (2,518). | AK15: 129225 | AM15: FY25 Group Scope 2 emissions (tCO2-e) (Market-based Electricity). | AN15: 0 | AP15: No specific total Scope 3 quantification found in the provided tables, although Scope 3 is included in the net zero target scope. | AQ15: 20 | AR15: 0.001349 | AS15: 0.001124
A16: MND-AU | B16: Monadelphous Group Ltd. | D16: KH | E16: Rebecca Voyer | F16: Invitation sent | R16: =IFERROR(_xlfn.XLOOKUP($A16,Profitability!$A$5:$A$342,Profitability!$Q$5:$Q$342),"na") | S16: =IFERROR(_xlfn.XLOOKUP($A16,Profitability!$A$5:$A$342,Profitability!$R$5:$R$342),"na") | T16: Public | U16: Australia | V16: 1981 | W16: 7375 | X16: 2153.156 | Y16: Pacific | Z16: Western Australia (WA) | AA16: 1005.23 | AB16: Monadelphous Group Ltd. provides construction, maintenance and industrial services to the resources, energy and infrastructure sectors. The firm's divisions include Engineering Construction; and Maintenance and Industrial Services. The Engineering Construction division provides large-scale multidisciplinary project management and construction services. The Maintenance and Industrial Services division specializes in the planning, management and execution of mechanical and electrical maintenance services, shutdowns, sustaining capital works, fixed plant maintenance services, access solutions, specialist coatings and rail maintenance services. . It operates through the following geographical segments: Australia, Chile, Papua New Guinea, Mongolia, and Other overseas locations. The company was founded in 1972 and is headquartered in Perth, Australia. | AC16: Specialty Contracting Services | AD16: Facilities and Construction Services | AE16: Industrial Services | AF16: Industrial Specialty Engineering Contractors | AH16: 6608 | AI16: 0.9 | AJ16: which the Company will reference,, ,"year ended 30 June 2025 was 6,608", progress of its Net Zero by 2050 and,, | AK16: 7599000 | AL16: 0.9 | AM16: figure is 7,599 tCO2-e. | AQ16: 22 | AR16: 0.038883 | AS16: 0.010218
A17: BSL-AU | B17: BlueScope Steel Ltd. | D17: KH | E17: Megan Wheeldon | F17: Invitation sent | P17: 6131585 | Q17: 806487 | R17: =IFERROR(_xlfn.XLOOKUP($A17,Profitability!$A$5:$A$342,Profitability!$Q$5:$Q$342),"na") | S17: =IFERROR(_xlfn.XLOOKUP($A17,Profitability!$A$5:$A$342,Profitability!$R$5:$R$342),"na") | T17: Public | U17: Australia | V17: 1921 | W17: 16500 | X17: 16294.4 | Y17: Pacific | Z17: Victoria (VIC) | AA17: 15781 | AB17: BlueScope Steel Ltd. engages in the manufacture of steel products. It operates through the following segments: Australian Steel Products, North Star BlueScope Steel, Buildings and Coated Products North America, Coated Products Asia, and New Zealand and Pacific Islands. The Australian Steel Products segment produces and markets coated and painted flat steel products. The North Star BlueScope Steel segment is a single site electric arc furnace producer of hot rolled coil. The Buildings and Coated Products North America segment includes engineered building solutions and servicing the low-rise non-residential construction needs of customers. The Coated Products Asia segment offers metal coated and painted steel building products. The New Zealand and Pacific Islands segment consists of New Zealand Steel, Pacific Steel, and BlueScope Pacific Islands business areas. The company was founded on July 15, 2002 and is headquartered in Melbourne, Australia. | AC17: Primary Metals Products | AD17: Metal Products | AE17: Mining and Mineral Products | AF17: Diversified Primary Metals Processors | AH17: 8500000 | AJ17: FY25 Scope 1 GHG emissions (8,500 ktCO2-e) | AK17: 1700000 | AM17: FY25 Scope 2 GHG emissions (1,700 ktCO2-e) | AN17: 12770000 | AP17: FY25 Scope 3 GHG emissions (12,770 ktCO2-e) | AQ17: 14 | AR17: 0.004554 | AS17: 0.000859
A18: FMG-AU | B18: Fortescue Ltd. | D18: KH | E18: Bronwyn Grieve | F18: Invitation sent | P18: 2002222 | Q18: 513963 | R18: =IFERROR(_xlfn.XLOOKUP($A18,Profitability!$A$5:$A$342,Profitability!$Q$5:$Q$342),"na") | S18: =IFERROR(_xlfn.XLOOKUP($A18,Profitability!$A$5:$A$342,Profitability!$R$5:$R$342),"na") | T18: Public | U18: Australia | V18: 1983 | W18: - | X18: 23996.69 | Y18: Pacific | Z18: Western Australia (WA) | AA18: 47844.664 | AB18: Fortescue Ltd. engages in the development of iron ore deposits. It operates through the Metals and Energy segments. The Metals segment includes exploration, development, production, processing, sale, and transportation of iron ore, and the exploration for other minerals. The Energy segment is involved in the development of green electricity, green hydrogen, and green ammonia projects. The company was founded by John Andrew Henry Forrest in April 2003 and is headquartered in East Perth, Australia. | AC18: Base Metal Mining | AD18: Metal Ore Mining | AE18: Mining and Mineral Products | AF18: Other Base Metal Ore Mining | AH18: 2640000 | AI18: 1 | AJ18: Total Group Scope 1,2.64,2.36,12.0% | AK18: 520000 | AL18: 1 | AM18: Australian terrestrial iron ore operations Scope 2 emissions (location-based),0.37,0.36,0.35 | AN18: 275880000 | AO18: 1 | AP18: Total Group Scope 3 emissions,275.88,269.31,2.4% | AQ18: 8 | AR18: 0.217039 | AS18: 0.000333
A19: WOR-AU | B19: Worley Ltd. | D19: KH | E19: Secondary only. Requested. | F19: Invitation sent | R19: =IFERROR(_xlfn.XLOOKUP($A19,Profitability!$A$5:$A$342,Profitability!$Q$5:$Q$342),"na") | S19: =IFERROR(_xlfn.XLOOKUP($A19,Profitability!$A$5:$A$342,Profitability!$R$5:$R$342),"na") | T19: Public | U19: Australia | V19: 2001 | W19: 45500 | X19: 11222 | Y19: Pacific | Z19: New South Wales (NSW) | AA19: 11019 | AB19: Worley Ltd. engages in the provision of services to the resources, energy, and industrial sectors. It operates through the following segments: Energy and Chemical Services, Mining, Minerals and Metal Services, Major Projects and Integrated Solutions and Advisian. The Energy and Chemical Services segment includes engineering, procurement, project management, program management, and operations. The Mining, Minerals and Metals Services segment line of business combines extensive local experience and innovative, integrated solutions with technically-led centers of excellence to explore process improvements, develop fit-for-purpose engineering and project execution, and accelerate the translation of customer objectives into actions that drive production and project certainty. The Major Projects and Integrated Solutions segment focuses on delivering projects that pose a level of commercial and reputational risk for Worley by the nature of their size, complexity and the scope of services and also engages in delivering integrated solutions, which include maintenance, modification, operations, engineering, fabrication, construction, hook-up and commissioning services to existing assets around the globe. The Advisian segment provides a true end-to-end offering integrating strategy, management and technical consulting expertise to clients in the hydrocarbons, resources and infrastructure sectors. The company was founded by John Michael Grill in 1971 and is headquartered in Sydney, Australia. | AC19: Infrastructure Construction/Contracting Services | AD19: Facilities and Construction Services | AE19: Industrial Services | AF19: Process Plants, Utilities and Energy Construction | AH19: 24485 | AI19: 1 | AJ19: "GHG emissions from diesel generators at four leased sites in India were reclassified from Scope 1 to Scope 3 – category 8, as they relate to base building operations" managed by landlords. This caused our Scope 1 & 2 emissions to decrease by approximately 27t CO2e. 27/38360 0.1% decrease in emissions compared to FY2024. Change in boundary | AK19: 6524 | AL19: 1 | AM19: We report Scope 2 emissions using both location-based and market-based methods as recommended by the GHG Protocol Scope 2 Guidance. | AN19: 1317095 | AO19: 1 | AP19: Our Climate Change Position Statement (CCPS) sets out the actions we’re taking in response to climate change. We are decarbonizing our business and are, "committed to reducing Scope 1 and 2 GHG emissions to net zero by 2030, and Scope 3 emissions by 2050. We plan to achieve our Scope 1 and 2 commitments", "through initiatives, such as reducing energy use and switching to renewable energy and low carbon fuels. We will achieve our Scope 3 commitments through working", | AQ19: 26 | AR19: 0.036446 | AS19: 0.002317
A20: VCX-AU | B20: Vicinity Centres | D20: KH | E20: Jason Temby | F20: Invitation sent | R20: =IFERROR(_xlfn.XLOOKUP($A20,Profitability!$A$5:$A$342,Profitability!$Q$5:$Q$342),"na") | S20: =IFERROR(_xlfn.XLOOKUP($A20,Profitability!$A$5:$A$342,Profitability!$R$5:$R$342),"na") | T20: Public | U20: Australia | V20: 1985 | W20: 1246 | X20: 1330.1 | Y20: Pacific | Z20: Victoria (VIC) | AA20: 16342.5 | AB20: Vicinity Centres operates as a real estate investment trust, which engages in the development, operation, and management of shopping centers. It operates through the following business segments: Property Investment and Strategic Partnerships. The Property Investment segment comprises of net property income derived from investment in retail property. The Strategic Partnerships segement offers property management, development, leasing, and management of wholesale property funds. The company was founded on February 18, 1985 and is headquartered in Chadstone, Australia. | AC20: Equity REITs | AD20: Real Estate Investment Trusts (REITs) | AE20: Real Estate | AF20: Equity REITs | AH20: 5516 | AI20: 1 | AJ20: === Table 6 (page 145) === "We reviewed a selection of performance metrics, as",,14 Gender 40:40:20 target,63:37:0 | AK20: 108143 | AL20: 1 | AM20: Total Scope 1 greenhouse gas (GHG) emissions,tCO2-e,"1,116",(28%),(53%) Total Scope 2 GHG emissions,tCO2-e,"36,816",0%,(38%) Total Scope 1 and Scope 2 GHG emissions,tCO2-e,"37,932",(1%),(38%) | AN20: 204469 | AO20: 1 | AP20: Total Scope 1 greenhouse gas (GHG) emissions,tCO2-e,"1,116",(28%),(53%) Total Scope 2 GHG emissions,tCO2-e,"36,816",0%,(38%) Total Scope 1 and Scope 2 GHG emissions,tCO2-e,"37,932",(1%),(38%) | AQ20: 17 | AR20: 0.755282 | AS20: 0.012781
A21: DXS-AU | B21: Dexus | D21: KH | E21: Ramana James | F21: Invitation sent | R21: =IFERROR(_xlfn.XLOOKUP($A21,Profitability!$A$5:$A$342,Profitability!$Q$5:$Q$342),"na") | S21: =IFERROR(_xlfn.XLOOKUP($A21,Profitability!$A$5:$A$342,Profitability!$R$5:$R$342),"na") | T21: Public | U21: Australia | V21: 2004 | W21: 900 | X21: 1007.6 | Y21: Pacific | Z21: New South Wales (NSW) | AA21: 15388.6 | AB21: Dexus engages in real estate investments, leasing, and tenant services. It operates through the following segments: Office, Industrial, Co-Investment, Property Management, Funds Management, Development and Trading, and All Other. The Office segment offers domestic space with any associated retail space, car parks, and developments. The Industrial segment consists of domestic industrial properties, industrial estates, and developments. The Co-Investment segment focuses on income distribution earned from investments in pooled real assets and funds. The Property Management segment provides management services for third party clients and owned assets. The Funds Management segment offers management of third-party client assets. The Development and Trading segment includes the revenue earned and costs incurred on developments and inventory. The All Other segment involves the corporate expenses associated with maintaining and operating, and the treasury function managed through a centralized treasury department. The company was founded in 2004 and is headquartered in Sydney, Australia. | AC21: Equity REITs | AD21: Real Estate Investment Trusts (REITs) | AE21: Real Estate | AF21: Equity REITs | AH21: 7669 | AI21: 1 | AJ21: Scope 1 GHG emissions,tCO2e,"7,669" | AK21: 0 | AL21: 1 | AM21: Scope 2 location-based GHG emissions,tCO2e,"90,686" | AN21: 26006 | AO21: 1 | AP21: Scope 3 location-based GHG emissions,tCO2e,"34,745" | AQ21: 22 | AR21: 0.003374 | AS21: 0.021834
A22: COH-AU | B22: Cochlear Ltd. | D22: KH | E22: Michael Grasso | F22: Invitation sent | R22: =IFERROR(_xlfn.XLOOKUP($A22,Profitability!$A$5:$A$342,Profitability!$Q$5:$Q$342),"na") | S22: =IFERROR(_xlfn.XLOOKUP($A22,Profitability!$A$5:$A$342,Profitability!$R$5:$R$342),"na") | T22: Public | U22: Australia | V22: 1983 | W22: 5500 | X22: 2355.8 | Y22: Pacific | Z22: New South Wales (NSW) | AA22: 2825.0001 | AB22: Cochlear Ltd. engages in the provision of implantable hearing solutions. The firm operates through the following geographical segments: Americas, EMEA, Asia Pacific, Corporate and Other. The company was founded by Michael S. Hirshorn in 1981 and is headquartered in Sydney, Australia. | AC22: Specialized Medical Devices | AD22: Other Medical Devices | AE22: Healthcare Equipment | AF22: Other Specialized Medical Devices | AH22: 951 | AI22: 1 | AJ22: pathway for adults,and services,"a culture of aspiration,",of initiatives to reduce our,,returns ,,"achievement, experimentation","Scope 1, 2 and 3 carbon",, • Develop the acoustic implant,• Support recipient access to,,,•,Improve efficiency and agility | AK22: 1980 | AL22: 1 | AM22: ,operate on 100% renewable energy. We are actively working to,,, Scope 1 and Scope 2 emissions,,,, ,expand renewable energy use across all locations.,,, | AN22: 66616 | AO22: 1 | AP22: ,"necessary to our operations, we are actively exploring viable",,,,,,,,, ,low-emission alternatives.,Scope 34,tCO2e,"66,616*","14,418","10,950","2,196",186,"4,774","18,630" ,,Carbon offsets5,tCO2e,"3,401","11,422","7,941","1,150",0,0,0 | AQ22: 2 | AR22: 0.165082 | AS22: 0.000849
A23: CWP-AU | B23: Cedar Woods Properties Ltd. | D23: KH | E23: Karl White | F23: Invitation sent | R23: =IFERROR(_xlfn.XLOOKUP($A23,Profitability!$A$5:$A$342,Profitability!$Q$5:$Q$342),"na") | S23: =IFERROR(_xlfn.XLOOKUP($A23,Profitability!$A$5:$A$342,Profitability!$R$5:$R$342),"na") | T23: Public | U23: Australia | V23: 1987 | W23: 93 | X23: 468.595 | Y23: Pacific | Z23: Western Australia (WA) | AA23: 857.68402 | AB23: Cedar Woods Properties Ltd. engages in property investment and development. The firm's principal interests are in urban land and built form development for residential, industrial and commercial purposes. Its projects include St. A in St Albans, Jackson Green in Clayton South, Williams Landing, Bushmead, Harrisdale Green, Ellendale, and Glenside. The company was founded by William George Hames and Ross James Neumann in 1987 and is headquartered in West Perth, Australia. | AC23: Other Real Estate Investment and Services | AD23: Real Estate Investment and Services | AE23: Real Estate | AF23: Real Estate Developers | AH23: 74 | AJ23: Reported as combined Scope 1 & 2 net Greenhouse Gas Emissions (t-CO2-e). | AK23: 74 | AM23: Reported as combined Scope 1 & 2 net Greenhouse Gas Emissions (t-CO2-e). | AN23: 0 | AP23: No specific Scope 3 total found. | AQ23: 0 | AR23: 0.102733 | AS23: 0
A24: CNI-AU | B24: Centuria Capital Group | D24: KH | E24: Andrew Scerri | F24: Invitation sent | R24: =IFERROR(_xlfn.XLOOKUP($A24,Profitability!$A$5:$A$342,Profitability!$Q$5:$Q$342),"na") | S24: =IFERROR(_xlfn.XLOOKUP($A24,Profitability!$A$5:$A$342,Profitability!$R$5:$R$342),"na") | T24: Public | U24: Australia | V24: 1980 | W24: - | X24: 431.797 | Y24: Pacific | Z24: New South Wales (NSW) | AA24: 3586.8881 | AB24: Centuria Capital Group is funds manager company. It operates through the following segments: Property Funds, Co-Investments, Developments, Property & Development Finance, Investment Bonds and Corporate. Property Funds Segment which specializes in listed and unlisted property funds. Co-Investments Segment provides direct interest in property funds, properties held for development and other liquid investments. Developments Segment gives completion of structured property developments which span sectors ranging from commercial office,industrial and health through to affordable housing and residential mixed use. Property and Development Finance Segment deals with provision of real estate secured non-bank finance for development projects, bridge finance and residual stock. Investment Bonds Segment including single and multi-premium investments. The company was founded in 1980 and is headquartered in Sydney, Australia. | AC24: Asset Management and Financial Advisory Services | AD24: Investment Services | AE24: Investment Services | AF24: Alternative Investment Managers | AQ24: 1 | AR24: 0.191518 | AS24: 0.002316
A25: CHC-AU | B25: Charter Hall Group | D25: KH | E25: Janaki Dhagat | F25: Invitation sent | R25: =IFERROR(_xlfn.XLOOKUP($A25,Profitability!$A$5:$A$342,Profitability!$Q$5:$Q$342),"na") | S25: =IFERROR(_xlfn.XLOOKUP($A25,Profitability!$A$5:$A$342,Profitability!$R$5:$R$342),"na") | T25: Public | U25: Australia | V25: 1991 | W25: - | X25: 687.8 | Y25: Pacific | Z25: New South Wales (NSW) | AA25: 3584.4001 | AB25: Charter Hall Group engages in managing and investing in office, retail, and industrial properties. It operates through the following segments: Property Investments, Development investments, and Funds Management. The Property Investments segment comprises an investment portfolio of property funds. The Development investments segment comprises investments in developments. The Funds Management segment offers investment management services and real estate management services. The company was founded by Cedric Fuchs and David John Southon in 1991 and is headquartered in Sydney, Australia. | AC25: Equity REITs | AD25: Real Estate Investment Trusts (REITs) | AE25: Real Estate | AF25: Equity REITs | AH25: 23741 | AI25: 0.9 | AJ25: ,"we are signatories, and prioritises reducing energy",, ,,"centres increased from 0.5MW to 17.5MW, coupled with","St, 480 Swan St and 60 King William St, have all-electric" reduction aligned to climate science.,"consumption, eliminating fossil fuels, and compensating",, | AK25: 100938 | AL25: 0.9 | AM25: In FY25 we achieved a 77% reduction,From 1 July our whole platform will,Nature-based carbon offsets,80% of the onsite solar across the,Achieved 48% waste diversion from in net Scope 1 and Scope 2 emissions1,operate at 100% renewable energy,(9% of total Scope 1 and Scope 2,Group supplied tenants with clean,landfill across Office and Shopping from our FY17 baseline.,supply in assets under operational,emissions) enabled us to achieve our,"energy, reducing our downstream",Centre Retail sites under operational | AN25: 280000 | AO25: 0.9 | AP25: ,"we are signatories, and prioritises reducing energy",, ,,"centres increased from 0.5MW to 17.5MW, coupled with","St, 480 Swan St and 60 King William St, have all-electric" reduction aligned to climate science.,"consumption, eliminating fossil fuels, and compensating",, | AQ25: 64 | AR25: 0.328293 | AS25: 0.09305
A26: SCG-AU | B26: Scentre Group | D26: KH | E26: Katie Moran | F26: Invitation sent | P26: 10046 | Q26: 179604 | R26: =IFERROR(_xlfn.XLOOKUP($A26,Profitability!$A$5:$A$342,Profitability!$Q$5:$Q$342),"na") | S26: =IFERROR(_xlfn.XLOOKUP($A26,Profitability!$A$5:$A$342,Profitability!$R$5:$R$342),"na") | T26: Public | U26: Australia | V26: 1959 | W26: 2860 | X26: 2637.1 | Y26: Pacific | Z26: New South Wales (NSW) | AA26: 36354.899 | AB26: Scentre Group engages in the business of owning, managing, leasing, and developing Westfield destinations in Australia and New Zealand. It operates under the Property Investment, and Property Management and Construction segments. The Property Investment segment includes net property income from shopping centers. The Property Management and Construction segment focuses on external fee income from third parties primarily property management and development fees, and associated business expenses. The company was founded in July 1959 and is headquartered in Sydney, Australia. | AC26: Equity REITs | AD26: Real Estate Investment Trusts (REITs) | AE26: Real Estate | AF26: Equity REITs | AH26: 10211 | AI26: 1 | AJ26: "Scope 1 GHG emissions in tonnes of carbon dioxide 10,211",,► National Greenhouse and Energy Reporting Act 2007 (for,,, equivalent (tCO2-e),,,,, | AK26: 175110 | AL26: 1 | AM26: "Scope 2 GHG emissions as calculated using the 175,110",,,,, ,,GHG Protocol Corporate Standard,,, | AN26: 72655 | AO26: 1 | AP26: "Selected Scope 3 GHG emissions (limited to waste to 72,655",K,,,, "landfill, purchased electricity, employee commute",ey responsibilities,,,, | AQ26: 0 | AR26: 0.398089 | AS26: 0
A27: S32-AU | B27: South32 Ltd. | D27: KH | E27: Jazmin Searson | F27: Invitation sent | P27: 5697621 | Q27: 308477 | R27: =IFERROR(_xlfn.XLOOKUP($A27,Profitability!$A$5:$A$342,Profitability!$Q$5:$Q$342),"na") | S27: =IFERROR(_xlfn.XLOOKUP($A27,Profitability!$A$5:$A$342,Profitability!$R$5:$R$342),"na") | T27: Public | U27: Australia | V27: 2000 | W27: 8892 | X27: 8924.8354 | Y27: Pacific | Z27: Western Australia (WA) | AA27: 20946.06 | AB27: South32 Ltd. operates as a metal and mining company. It operates through the following segments: Worsley Alumina, Hillside Aluminium, Mozal Aluminium, Brazil Alumina, South Africa Energy Coal, Illawarra Metallurgical Coal, Eagle Downs Metallurgical Coal, Australia Manganese, South Africa Managanese, Cerro Matoso, Cannington, and Hermosa. The Worsley Alumina segment offers bauxite mine and alumina refinery in Western Australia. The Hillside Aluminium segment offers aluminium smelters at Richards Bay, South Africa. The Mozal Aluminium segment includes aluminium smelter in Mozambique. The Brazil Alumina segment covers alumina refinery in Brazil. The South Africa Energy Coal segment comprises of open-cut and underground energy coal mines and processing operations in South Africa. The Illawarra Metallurgical Coal segment consists of underground metallurgical coal mines in New South Wales, Australia. The Eagle Downs Metallurgical Coal segment involves in the exploration and development of metallurgical coal deposit in Queensland, Australia. The Australia Manganese segment produces manganese ore in the Northern Territory and manganese alloys in Tasmania. The South Africa Manganese segment involves in the production of ore and alloy in South Africa. The Cerro Matoso segment includes laterite ferronickel mining and smelting complex in Colombia. The Cannington segment explores silver, lead, and zinc. The Hermosa segment involves in exploration and development option for zinc, lead and silver sulphide deposit in Tucson, United States. The company was founded on July 12, 2000 and is headquartered in Perth, Australia. | AC27: Primary Metals Products | AD27: Metal Products | AE27: Mining and Mineral Products | AF27: Alumina and Aluminum Products Manufacturing | AH27: 7400000 | AI27: 1 | AJ27: Total high potential injuries,, ,0.2, and illnesses frequency (HPIIF),, | AK27: 17300000 | AL27: 1 | AM27: US$10.5 million exceeded our target of US$3.63 million.,Worsley Alumina’s Scope 1 emissions and a 4.2% reduction in total ,"Scope 1 emissions42, both relative to FY21 levels. However, in FY25" In Australia we are committed to increasing our procurement of, | AN27: 22700000 | AO27: 1 | AP27: Total high potential injuries,, ,0.2, and illnesses frequency (HPIIF),, | AQ27: 15 | AR27: 0.055017 | AS27: 0.001681
A28: SHA-AU | B28: Shape Australia Corp. Ltd. | D28: KH | E28: Shane Morgan | F28: Invitation sent | R28: =IFERROR(_xlfn.XLOOKUP($A28,Profitability!$A$5:$A$342,Profitability!$Q$5:$Q$342),"na") | S28: =IFERROR(_xlfn.XLOOKUP($A28,Profitability!$A$5:$A$342,Profitability!$R$5:$R$342),"na") | T28: Public | U28: Australia | V28: 2021 | W28: 686 | X28: 947.64 | Y28: Pacific | Z28: New South Wales (NSW) | AA28: 275.06601 | AB28: Shape Australia Corp. Ltd. operates an end-to-end service and delivery model across the project lifecycle, from new build, fit-out and refurbishment, and recurring minor works. The firm is focused on commercial fit-out and refurbishments, with select capabilities in new build. It acts as a head contractor on fit-out and refurbishment projects across Australia, with capabilities across a range of projects and services. The company was founded in 1989 and is headquartered in Sydney, Australia. | AC28: Specialty Contracting Services | AD28: Facilities and Construction Services | AE28: Industrial Services | AF28: Commercial Specialty Engineering Contractors | AQ28: 0 | AR28: 0.02229 | AS28: 0
A29: MQG-AU | B29: Macquarie Group Ltd. | D29: KH | E29: Mary Ann van Bodegraven | F29: Invitation sent | R29: =IFERROR(_xlfn.XLOOKUP($A29,Profitability!$A$5:$A$342,Profitability!$Q$5:$Q$342),"na") | S29: =IFERROR(_xlfn.XLOOKUP($A29,Profitability!$A$5:$A$342,Profitability!$R$5:$R$342),"na") | T29: Public | U29: Australia | V29: 2006 | W29: 19735 | X29: 32008 | Y29: Pacific | Z29: New South Wales (NSW) | AA29: 446434.01 | AB29: Macquarie Group Ltd. operates as a non-operating holding company. The firm engages in the provision of banking, financial, advisory, investment and funds management services. It operates through the following segments: Macquarie Asset Management (MAM), Banking and Financial Services (BFS), Commodities and Global Markets (CGM), Macquarie Capital and Corporate. The MAM segment delivers investment solutions to clients across a range of capabilities, including infrastructure, real estate, agriculture, equities, fixed income, private credit, liquid alternatives, and multi-asset solutions. The BFS segment offers personal banking, wealth management, business banking, and vehicle finance products and services to retail clients, advisers, brokers and business clients. The CGM segment comprises of integrated, end-to-end offering across global markets including equities, fixed income, foreign exchange, and commodities. The Macquarie Capital segment includes capital solutions across products and sectors including infrastructure, green and conventional energy. The Corporate segment refers to the head office and central service groups, including group treasury and other investments. The company was founded on December 10, 1969 and is headquartered in Sydney, Australia. | AC29: Diversified Investment | AD29: Investment Services | AE29: Investment Services | AF29: Diversified Investment | AH29: 482 | AJ29: FY25 Scope 1 emissions (tCO2e). | AK29: 0 | AM29: FY25 Scope 2 emissions (tCO2e). Scope 2 emissions reduced to zero since FY2022 due to the purchase of 100% renewable electricity equivalent. | AN29: 227896 | AP29: FY25 Total Scope 3 (Categories 1-6 & 8) operational emissions (tCO2e). | AQ29: 24 | AR29: 0.111941 | AS29: 0.00075
A30: Private | B30: CDC | D30: KH | E30: Nicholas Blay | F30: Invitation sent | R30: =IFERROR(_xlfn.XLOOKUP($A30,Profitability!$A$5:$A$342,Profitability!$Q$5:$Q$342),"na") | S30: =IFERROR(_xlfn.XLOOKUP($A30,Profitability!$A$5:$A$342,Profitability!$R$5:$R$342),"na") | AH30: 929 | AI30: 1 | AJ30: ,when compared to on-premises energy,,external partners and their suppliers the early vision for the company.,,"carbon by 2030 for Scope 1, 2 and", ,"consumption. At the same time, the data",,for their important role in driving a | AK30: 78601 | AL30: 1 | AM30: ,,is a particularly pertinent challenge in countries like, ,an average Water Usage Effectiveness of 0.01. CDC’s closed-loop chilled water system consumes almost,, ,,"Australia, where severe droughts can significantly",This innovation is considered a genuine game | AN30: 0 | AQ30: 13
A31: ING-AU | B31: Inghams Group Ltd. | D31: KH | E31: Naomi Martin | F31: Invitation sent | P31: 63131 | Q31: 131449 | R31: =IFERROR(_xlfn.XLOOKUP($A31,Profitability!$A$5:$A$342,Profitability!$Q$5:$Q$342),"na") | S31: =IFERROR(_xlfn.XLOOKUP($A31,Profitability!$A$5:$A$342,Profitability!$R$5:$R$342),"na") | T31: Public | U31: Australia | V31: 2013 | W31: - | X31: 3152.4 | Y31: Pacific | Z31: New South Wales (NSW) | AA31: 2364.3001 | AB31: Inghams Group Ltd. engages in the production and sale of chicken and turkey products. It operates through the Australia and New Zealand geographical segment. The company was founded in 1918 and is headquartered in North Ryde, Australia. | AC31: Food Production | AD31: Food and Beverage Production | AE31: Food and Tobacco Production | AF31: Meat and Seafood Production | AH31: 55812 | AI31: 1 | AJ31: Scope 1 GHG emissions (tCO2-eq),"55,812" | AK31: 128861 | AL31: 1 | AM31: Scope 2 GHG emissions (tCO2-eq) (location based),"128,861" | AN31: 0 | AO31: 0.95 | AP31: Production (t),"1,993,887" Scope 1 GHG emissions (tCO2-eq),"55,812" Scope 2 GHG emissions (tCO2-eq) (location based),"128,861" | AQ31: 0 | AR31: 0.028488 | AS31: 0
A32: DCFCQ-US | B32: Tritium DCFC Ltd. | C32: I thought they went into liquidation? Or was it just administration | D32: KH | E32: Sean Simmons | F32: Invitation sent | R32: =IFERROR(_xlfn.XLOOKUP($A32,Profitability!$A$5:$A$342,Profitability!$Q$5:$Q$342),"na") | S32: =IFERROR(_xlfn.XLOOKUP($A32,Profitability!$A$5:$A$342,Profitability!$R$5:$R$342),"na") | T32: Public | U32: Australia | V32: 2021 | W32: 1001 | X32: 274.35455 | Y32: Pacific | Z32: Queensland (QLD) | AA32: 413.39443 | AB32: Tritium DCFC Ltd. designs and manufactures proprietary hardware and software to develop direct current chargers for electric vehicles. It operates through the following segments: Hardware, Software, and Service and Maintenance. The company was founded by David Finn, Paul Serina and James Kennedy on May 7, 2021 and is headquartered in Murarrie, Australia. | AC32: Commercial and Industrial Electric Products | AD32: Electrical Equipment and Power Systems | AE32: Industrial Manufacturing | AF32: General Industrial Electrical Products
A33: TLS-AU | B33: Telstra Group Ltd. | D33: KH | E33: Justine Rowe | F33: Invitation sent | P33: 32771 | Q33: 757967 | R33: =IFERROR(_xlfn.XLOOKUP($A33,Profitability!$A$5:$A$342,Profitability!$Q$5:$Q$342),"na") | S33: =IFERROR(_xlfn.XLOOKUP($A33,Profitability!$A$5:$A$342,Profitability!$R$5:$R$342),"na") | T33: Public | U33: Australia | V33: 1992 | W33: 30553 | X33: 23125 | Y33: Pacific | Z33: Victoria (VIC) | AA33: 44968.001 | AB33: Telstra Group Ltd. engages in the provision of telecommunications and technology services. It operates through the following segments: Telstra Consumer and Small Business (TC&SB), Telstra Enterprise (TE), Networks and IT (N&IT), Telstra InfraCo, and All Other. The TC&SB segment consists of telecommunication, media, and technology products and services to consumer and small business customers, using mobile and fixed network technologies. The TE segment offers telecommunication services, technology solutions, network capacity and management, unified communications, cloud, security, industry solutions, and monitoring services to government and large enterprise. The N&IT segment maintains reliability and security network platforms and data. Telstra InfraCo covers telecommunication products and services delivered over Telstra networks to other carriers, carriage service providers, and internet service providers. The company was founded in 1992 and is headquartered in Melbourne, Australia. | AC33: Pan-Asia/Pacific Mixed Telecommunications Services | AD33: General Telecommunications Services | AE33: Telecommunications | AF33: Australia/New Zealand Mixed Telecom Services | AH33: 31794 | AJ33: FY25 Scope 1 total emissions (tCO2e). Calculated using location-based methodology for S1&S2. | AK33: 703989 | AM33: FY25 Scope 2 total emissions (tCO2e). Calculated using location-based methodology for S1&S2. | AN33: 1454930 | AP33: FY25 Scope 3 total emissions (tCO2e) (aligned to GHG protocol). | AQ33: 6 | AR33: 0.093924 | AS33: 0.000259
A34: LLC-AU | B34: Lendlease Group | D34: KH | E34: Darryl Stuckey | F34: Request message sent | P34: 15951 | Q34: 79159 | R34: =IFERROR(_xlfn.XLOOKUP($A34,Profitability!$A$5:$A$342,Profitability!$Q$5:$Q$342),"na") | S34: =IFERROR(_xlfn.XLOOKUP($A34,Profitability!$A$5:$A$342,Profitability!$R$5:$R$342),"na") | T34: Public | U34: Australia | V34: 1958 | W34: - | X34: 7786 | Y34: Pacific | Z34: New South Wales (NSW) | AA34: 14562 | AB34: Lendlease Group operates as a property and infrastructure development company. It engages in designing, developing, constructing, funding, owning, co-investing or managing property, and infrastructure assets. The firm operates through the following segments: Investments, Development, Construction, and Capital Release Unit. The Investments segment includes an investment management platform and the group's ownership interests in residential, office, retail, industrial, retirement and infrastructure investment assets. The Development segment includes the development of inner-city mixed-use developments, apartments, communities, retirement, retail, commercial assets and social and economic infrastructure. The Construction segment includes the provision of project management, design and construction services, predominantly in the commercial, residential, mixed use, defense, and social infrastructure sectors. The Capital Release Unit segment includes overseas construction operations, overseas development projects, the group’s residual ownership interest in retirement assets and the US Military Housing business, Australian communities projects and the retained engineering and services projects. The company was founded by Gerardus Jozef Dusseldorp in 1957 and is headquartered in Barangaroo, Australia. | AC34: Infrastructure Construction/Contracting Services | AD34: Facilities and Construction Services | AE34: Industrial Services | AF34: Diverse Construction and Engineering Services | AH34: 23715 | AJ34: FY25 Gross Scope 1 Emissions (tCO2-eq). | AK34: 0 | AM34: FY25 Gross Scope 2 Emissions (Market-based Method) (tCO2-eq). Market-based emissions resulted in zero due to application of renewable electricity purchases/offsets. | AN34: 1353639 | AP34: FY25 Total Scope 3 Emissions (tCO2-eq). | AQ34: 0 | AR34: 0.028898 | AS34: 0
A35: NXT-AU | B35: NextDC Ltd. | D35: KH | E35: Nishi Vissamraju | F35: Request message sent | P35: 1614 | Q35: 335627 | R35: =IFERROR(_xlfn.XLOOKUP($A35,Profitability!$A$5:$A$342,Profitability!$Q$5:$Q$342),"na") | S35: =IFERROR(_xlfn.XLOOKUP($A35,Profitability!$A$5:$A$342,Profitability!$R$5:$R$342),"na") | T35: Public | U35: Australia | V35: 2010 | W35: 310 | X35: 427.209 | Y35: Pacific | Z35: Queensland (QLD) | AA35: 5688.6871 | AB35: NextDC Ltd. engages in the operation and development of data centers. It operates through the following segments: Vic, NSW/ACT, Rest of Australia, International, and Other. The company was founded by Bevan Andrew Slattery on May 11, 2010, and is headquartered in Brisbane, Australia. | AC35: Internet Hosting Services | AD35: Internet and Data Services | AE35: Software and Consulting | AF35: Colocation and Data Center Services | AH35: 7927 | AI35: 1 | AJ35: ,,,,,,, Climate,"In FY25, our Scope 1 emissions totalled 7,927 tCO2-e,",emission,emission,,,, ,primarily driven by diesel consumption for backup,source,source,,,, | AK35: 358348 | AL35: 1 | AM35: ,environmental,,,, ,0,,,,Social highlights ,,,,, | AN35: 0 | AQ35: 13 | AR35: -0.141718 | AS35: 0.03043
A36: PRN-AU | B36: Perenti Ltd. | D36: Vishal | E36: Darren Batchler | F36: Request message sent | R36: =IFERROR(_xlfn.XLOOKUP($A36,Profitability!$A$5:$A$342,Profitability!$Q$5:$Q$342),"na") | S36: =IFERROR(_xlfn.XLOOKUP($A36,Profitability!$A$5:$A$342,Profitability!$R$5:$R$342),"na") | T36: Public | U36: Australia | V36: 1986 | W36: 10290 | X36: 3489.546 | Y36: Pacific | Z36: Western Australia (WA) | AA36: 3416.6921 | AB36: Perenti Ltd. is a mining and energy services company, which engages in the provision of exploration, mine development, surfacing and underground mining, and energy and infrastructure services. It operates through the following segments: Contract Mining, Drilling Services, Mining and Technology Services, and Corporate. The Contract Mining segment provides underground and surface contract mining services. The Drilling Services segment offers drilling services across all stages of the mine life cycle. The Mining and Technology Services segment includes equipment hire, equipment parts and sales, supply of equipment, logistics services, and technology driven products and services. The Corporate segment focuses on corporate activity covering strategy, treasury, accounting, human resources, information technology, procurement, legal, risk, investor relations, and other corporate administration. The company was founded by James Edward Askew and Ronald George Sayers in 1987 and is headquartered in Perth, Australia. | AC36: Specialty Contracting Services | AD36: Facilities and Construction Services | AE36: Industrial Services | AF36: Industrial Specialty Engineering Contractors | AH36: 2004 | AI36: 1 | AJ36: ,,OUR SUSTAINABILITY TARGETS,,, ,,,female executive and,,scope 1 and 2 ,,,,, | AK36: 2969 | AL36: 1 | AM36: Greenhouse gas emissions – Scope 2 (market-based),"1,834 tonnes CO2-e" Greenhouse gas emissions – Scope 2 (location-based),"2,969 tonnes CO2-e" | AN36: 0 | AO36: 0.9 | AP36: ,,OUR SUSTAINABILITY TARGETS,,, ,,,female executive and,,scope 1 and 2 ,,,,, | AQ36: 8 | AR36: 0.034565 | AS36: 0.002293
A37: NCK-AU | B37: Nick Scali Ltd. | D37: Vishal | E37: Angus McDonald | F37: Request message sent | R37: =IFERROR(_xlfn.XLOOKUP($A37,Profitability!$A$5:$A$342,Profitability!$Q$5:$Q$342),"na") | S37: =IFERROR(_xlfn.XLOOKUP($A37,Profitability!$A$5:$A$342,Profitability!$R$5:$R$342),"na") | T37: Public | U37: Australia | V37: 1962 | W37: 850 | X37: 495.283 | Y37: Pacific | Z37: New South Wales (NSW) | AA37: 705.80702 | AB37: Nick Scali Ltd. engages in the sourcing and retailing of household furniture and related accessories. It offers sofas and armchairs, rugs and accessories, and furniture for living, dining, and bedroom. The company was founded by Nicodemo Domenico Scali in 1962 and is headquartered in North Ryde, Australia. | AC37: Furniture and Home Furnishings Stores | AD37: Home Improvement Retail | AE37: Consumer Retail | AF37: Furniture Stores | AQ37: 0 | AR37: 0.116451 | AS37: 0
A38: STO-AU | B38: Santos Ltd. | D38: Vishal | E38: James Murphy | F38: Request message sent | M38: 2024 | N38: =4.44*10^6 | O38: =0.8*10^6 | P38: 4233840 | Q38: 733963 | R38: =IFERROR(_xlfn.XLOOKUP($A38,Profitability!$A$5:$A$342,Profitability!$Q$5:$Q$342),"na") | S38: =IFERROR(_xlfn.XLOOKUP($A38,Profitability!$A$5:$A$342,Profitability!$R$5:$R$342),"na") | T38: Public | U38: Australia | V38: 1954 | W38: 3958 | X38: 8298.981 | Y38: Pacific | Z38: South Australia (SA) | AA38: 49855.445 | AB38: Santos Ltd. engages in the exploration, development, transportation, and marketing of natural gas. It operates through the following segments: Cooper Basin, Queensland and New South Wales, Papua New Guinea, Northern Australia and Timor-Leste, and Western Australia. The company was founded by Reg Sprigg, John Bonython, and Douglas Mawson on March 18, 1954 and is headquartered in Adelaide, Australia. | AC38: Other Pipeline and Energy Storage Services | AD38: Midstream Energy | AE38: Downstream and Midstream Energy | AF38: Other Pipeline and Energy Storage Services | AH38: 4440000 | AJ38: 2024 Gross operated Scope 1 greenhouse gas emissions (4.44 MtCO2e). | AK38: 800000 | AM38: 2024 Gross operated Scope 2 greenhouse gas emissions (0.80 MtCO2e). | AN38: 29900000 | AP38: 2024 Total Scope 3 emissions (29.9 MtCO2e). | AQ38: 4 | AR38: 0.223602 | AS38: 0.000482
